Workbook

Sheet Type
A1: Type | B1: Type #
A2: Category | B2: 14
A3: Class | B3: 8
A4: Collection | B4: 15
A5: Epic | B5: 10
A6: Event | B6: 12
A7: Explorer | B7: 3
A8: Hobby | B8: 16
A9: Lore | B9: 6
A10: Meta | B10: 2
A11: Quest | B11: 5
A12: Race | B12: 9
A13: Reputation | B13: 7
... A17: Vocation | B17: 13

Sheet Faction
A1: Faction | B1: Faction #
A2: Algraig, Men of Enedwaith | B2: 18
A3: Armoury District | B3: 39
A4: Bank District | B4: 40
A5: Builders' Fellowship | B5: 54
A6: Burgsmen's Fellowship | B6: 52
A7: Chicken Chasing League of Eriador | B7: 7
A8: Conquest of Gorgoroth | B8: 60
A9: Council of the North | B9: 12
A10: Defenders of Minas Tirith | B10: 51
A11: Docks District | B11: 41
A12: Dol Amroth | B12: 36
A13: Dol Amroth City Watch | B13: 37
... A77: Wilderfolk | B77: 72

Sheet Class
A1: Beorning | B1: 214
A2: Burglar | B2: 40
A3: Champion | B3: 172
A4: Guardian | B4: 23
A5: Hunter | B5: 162
A6: Lore Master | B6: 185
A7: Minstrel | B7: 31
A8: Rune-keeper | B8: 193
A9: Warden | B9: 194
A12: Max Length: | B12: 3

Sheet Race
A1: Beorning | B1: 114
A2: Dwarf | B2: 73
A3: Elf | B3: 65
A4: High Elf | B4: 117
A5: Hobbit | B5: 81
A6: Man | B6: 23
A7: Undefined | B7: 0

Sheet Vocation
A1: Armorer | B1: 7
A2: Armsman | B2: 5
A3: Explorer | B3: 1
A4: Historian | B4: 4
A5: None | B5: 0
A6: Tinker | B6: 2
A7: Woodsman | B7: 6
A8: Yeoman | B8: 3
A12: Max Length: | B12: 3

Sheet Fishing
A1: ID | B1: Save Index | C1: Name | D1: TYPE | E1: VXP | F1: Title | G1: LP | H1: REP | I1: FACTION | J1: SUMMARY | K1: DESC | L1: TIER | M1: Category ID | N1: Output parts | O1: Minimal | P1: Complete | Q1: QuestNumber | R1: Index | S1: ID | T1: ID (short) | U1: Category ID | V1: Save Index | W1: TYPE_INT | X1: Type | Y1: VXP_NUM | Z1: VXP | AA1: LP_NUM | AB1: LP | AC1: REP_NUM | AD1: REP | AE1: FACTION_INT | AF1: FACTION | AG1: TIER | AH1: NAME | AI1: LORE | AJ1: SUMMARY | AK1: TITLE | AL1: End
A2: 1879115029 | B2: 1 | C2: Darter-master | D2: Reputation | F2: Darter-master | I2: None | J2: Catch all 9 Darter varieties | K2: Catching all nine darters is no easy task! | L2: 0 | O2: =CONCATENATE(R2,T2,U2,AL2," -- ",C2) -> [1] = {["ID"] = 1879115029; }; -- Darter-master | P2: =CONCATENATE(R2,S2,V2,X2,Z2,AB2,AD2,AF2,AG2,AH2,AI2,AJ2,AK2,AL2) -> [1] = {["ID"] = 1879115029; ["SAVE_INDEX"] = 1; ["TYPE"] = 7; ["VXP"] = 0; ["LP"] = 0; ["REP"] = 0; ["FACTION"] = 1; ["TIER"] = 0; ["NAME"] = { ["EN"] = "Darter-master"; }; ["LORE"] = { ["EN"] = "Catching all nine darters is no easy task!"; }; ["SUMMARY"] = { ["EN"] = "Catch all 9 Darter varieties"; }; ["TITLE"] = { ["EN"] = "Darter-master"; }; }; | Q2: =ROW()-1 -> 1 | R2: =CONCATENATE(REPT(" ",3-LEN(Q2)),"[",Q2,"] = {") -> [1] = { | S2: =IF(LEN(A2)>0,CONCATENATE("[""ID""] = ",A2,"; ")," ") -> ["ID"] = 1879115029; | T2: =IF(LEN(A2)>0,CONCATENATE("[""ID""] = ",A2,"; "),"") -> ["ID"] = 1879115029; | U2: =IF(LEN(M2)>0,CONCATENATE("[""CAT_ID""] = ",M2,"; "),"") | V2: =IF(LEN(B2)>0,CONCATENATE("[""SAVE_INDEX""] = ",REPT(" ",1-LEN(B2)),B2,"; "),"") -> ["SAVE_INDEX"] = 1; | W2: =VLOOKUP(D2,Type!A$2:B$17,2,FALSE) -> 7 | X2: =CONCATENATE("[""TYPE""] = ",REPT(" ",2-LEN(W2)),W2,"; ") -> ["TYPE"] = 7; | Y2: =TEXT(E2,0) -> 0 | Z2: =CONCATENATE("[""VXP""] = ",REPT(" ",1-LEN(Y2)),TEXT(Y2,"0"),"; ") -> ["VXP"] = 0; | AA2: =TEXT(G2,0) -> 0 | AB2: =CONCATENATE("[""LP""] = ",REPT(" ",1-LEN(AA2)),TEXT(AA2,"0"),"; ") -> ["LP"] = 0; | AC2: =TEXT(H2,0) -> 0 | AD2: =CONCATENATE("[""REP""] = ",REPT(" ",1-LEN(AC2)),TEXT(AC2,"0"),"; ") -> ["REP"] = 0; | AE2: =VLOOKUP(I2,Faction!A$2:B$77,2,FALSE) -> 1 | AF2: =CONCATENATE("[""FACTION""] = ",TEXT(AE2,"0"),"; ") -> ["FACTION"] = 1; | AG2: =CONCATENATE("[""TIER""] = ",TEXT(L2,"0"),"; ") -> ["TIER"] = 0; | AH2: =CONCATENATE("[""NAME""] = { [""EN""] = """,C2,"""; }; ") -> ["NAME"] = { ["EN"] = "Darter-master"; }; | AI2: =CONCATENATE("[""LORE""] = { [""EN""] = """,K2,"""; }; ") -> ["LORE"] = { ["EN"] = "Catching all nine darters is no easy task!"; }; | AJ2: =CONCATENATE("[""SUMMARY""] = { [""EN""] = """,J2,"""; }; ") -> ["SUMMARY"] = { ["EN"] = "Catch all 9 Darter varieties"; }; | AK2: =IF(LEN(F2)>0,CONCATENATE("[""TITLE""] = { [""EN""] = """,F2,"""; }; "),"") -> ["TITLE"] = { ["EN"] = "Darter-master"; }; | AL2: =CONCATENATE("};") -> };
A3: 1879206842 | B3: 2 | C3: Fortunate Festival Fishes | D3: Event | F3: Rare Fish | I3: None | J3: Catch 10 of 4 types of fish during summer-festival | K3: You catch many rare and wondrous fish during the Summer Festival. | L3: 0 | O3: =CONCATENATE(R3,T3,U3,AL3," -- ",C3) -> [2] = {["ID"] = 1879206842; }; -- Fortunate Festival Fishes | P3: =CONCATENATE(R3,S3,V3,X3,Z3,AB3,AD3,AF3,AG3,AH3,AI3,AJ3,AK3,AL3) -> [2] = {["ID"] = 1879206842; ["SAVE_INDEX"] = 2; ["TYPE"] = 12; ["VXP"] = 0; ["LP"] = 0; ["REP"] = 0; ["FACTION"] = 1; ["TIER"] = 0; ["NAME"] = { ["EN"] = "Fortunate Festival Fishes"; }; ["LORE"] = { ["EN"] = "You catch many rare and wondrous fish during the Summer Festival."; }; ["SUMMARY"] = { ["EN"] = "Catch 10 of 4 types of fish during summer-festival"; }; ["TITLE"] = { ["EN"] = "Rare Fish"; }; }; | Q3: =ROW()-1 -> 2 | R3: =CONCATENATE(REPT(" ",3-LEN(Q3)),"[",Q3,"] = {") -> [2] = { | S3: =IF(LEN(A3)>0,CONCATENATE("[""ID""] = ",A3,"; ")," ") -> ["ID"] = 1879206842; | T3: =IF(LEN(A3)>0,CONCATENATE("[""ID""] = ",A3,"; "),"") -> ["ID"] = 1879206842; | U3: =IF(LEN(M3)>0,CONCATENATE("[""CAT_ID""] = ",M3,"; "),"") | V3: =IF(LEN(B3)>0,CONCATENATE("[""SAVE_INDEX""] = ",REPT(" ",1-LEN(B3)),B3,"; "),"") -> ["SAVE_INDEX"] = 2; | W3: =VLOOKUP(D3,Type!A$2:B$17,2,FALSE) -> 12 | X3: =CONCATENATE("[""TYPE""] = ",REPT(" ",2-LEN(W3)),W3,"; ") -> ["TYPE"] = 12; | Y3: =TEXT(E3,0) -> 0 | Z3: =CONCATENATE("[""VXP""] = ",REPT(" ",1-LEN(Y3)),TEXT(Y3,"0"),"; ") -> ["VXP"] = 0; | AA3: =TEXT(G3,0) -> 0 | AB3: =CONCATENATE("[""LP""] = ",REPT(" ",1-LEN(AA3)),TEXT(AA3,"0"),"; ") -> ["LP"] = 0; | AC3: =TEXT(H3,0) -> 0 | AD3: =CONCATENATE("[""REP""] = ",REPT(" ",1-LEN(AC3)),TEXT(AC3,"0"),"; ") -> ["REP"] = 0; | AE3: =VLOOKUP(I3,Faction!A$2:B$77,2,FALSE) -> 1 | AF3: =CONCATENATE("[""FACTION""] = ",TEXT(AE3,"0"),"; ") -> ["FACTION"] = 1; | AG3: =CONCATENATE("[""TIER""] = ",TEXT(L3,"0"),"; ") -> ["TIER"] = 0; | AH3: =CONCATENATE("[""NAME""] = { [""EN""] = """,C3,"""; }; ") -> ["NAME"] = { ["EN"] = "Fortunate Festival Fishes"; }; | AI3: =CONCATENATE("[""LORE""] = { [""EN""] = """,K3,"""; }; ") -> ["LORE"] = { ["EN"] = "You catch many rare and wondrous fish during the Summer Festival."; }; | AJ3: =CONCATENATE("[""SUMMARY""] = { [""EN""] = """,J3,"""; }; ") -> ["SUMMARY"] = { ["EN"] = "Catch 10 of 4 types of fish during summer-festival"; }; | AK3: =IF(LEN(F3)>0,CONCATENATE("[""TITLE""] = { [""EN""] = """,F3,"""; }; "),"") -> ["TITLE"] = { ["EN"] = "Rare Fish"; }; | AL3: =CONCATENATE("};") -> };
A4: 1879115020 | B4: 3 | C4: Sturgeon-master | D4: Reputation | F4: Sturgeon-master | I4: None | J4: Catch all 9 Sturgeon varieties | K4: Catching nine types of sturgeon will not be easy! | L4: 0 | O4: =CONCATENATE(R4,T4,U4,AL4," -- ",C4) -> [3] = {["ID"] = 1879115020; }; -- Sturgeon-master | P4: =CONCATENATE(R4,S4,V4,X4,Z4,AB4,AD4,AF4,AG4,AH4,AI4,AJ4,AK4,AL4) -> [3] = {["ID"] = 1879115020; ["SAVE_INDEX"] = 3; ["TYPE"] = 7; ["VXP"] = 0; ["LP"] = 0; ["REP"] = 0; ["FACTION"] = 1; ["TIER"] = 0; ["NAME"] = { ["EN"] = "Sturgeon-master"; }; ["LORE"] = { ["EN"] = "Catching nine types of sturgeon will not be easy!"; }; ["SUMMARY"] = { ["EN"] = "Catch all 9 Sturgeon varieties"; }; ["TITLE"] = { ["EN"] = "Sturgeon-master"; }; }; | Q4: =ROW()-1 -> 3 | R4: =CONCATENATE(REPT(" ",3-LEN(Q4)),"[",Q4,"] = {") -> [3] = { | S4: =IF(LEN(A4)>0,CONCATENATE("[""ID""] = ",A4,"; ")," ") -> ["ID"] = 1879115020; | T4: =IF(LEN(A4)>0,CONCATENATE("[""ID""] = ",A4,"; "),"") -> ["ID"] = 1879115020; | U4: =IF(LEN(M4)>0,CONCATENATE("[""CAT_ID""] = ",M4,"; "),"") | V4: =IF(LEN(B4)>0,CONCATENATE("[""SAVE_INDEX""] = ",REPT(" ",1-LEN(B4)),B4,"; "),"") -> ["SAVE_INDEX"] = 3; | W4: =VLOOKUP(D4,Type!A$2:B$17,2,FALSE) -> 7 | X4: =CONCATENATE("[""TYPE""] = ",REPT(" ",2-LEN(W4)),W4,"; ") -> ["TYPE"] = 7; | Y4: =TEXT(E4,0) -> 0 | Z4: =CONCATENATE("[""VXP""] = ",REPT(" ",1-LEN(Y4)),TEXT(Y4,"0"),"; ") -> ["VXP"] = 0; | AA4: =TEXT(G4,0) -> 0 | AB4: =CONCATENATE("[""LP""] = ",REPT(" ",1-LEN(AA4)),TEXT(AA4,"0"),"; ") -> ["LP"] = 0; | AC4: =TEXT(H4,0) -> 0 | AD4: =CONCATENATE("[""REP""] = ",REPT(" ",1-LEN(AC4)),TEXT(AC4,"0"),"; ") -> ["REP"] = 0; | AE4: =VLOOKUP(I4,Faction!A$2:B$77,2,FALSE) -> 1 | AF4: =CONCATENATE("[""FACTION""] = ",TEXT(AE4,"0"),"; ") -> ["FACTION"] = 1; | AG4: =CONCATENATE("[""TIER""] = ",TEXT(L4,"0"),"; ") -> ["TIER"] = 0; | AH4: =CONCATENATE("[""NAME""] = { [""EN""] = """,C4,"""; }; ") -> ["NAME"] = { ["EN"] = "Sturgeon-master"; }; | AI4: =CONCATENATE("[""LORE""] = { [""EN""] = """,K4,"""; }; ") -> ["LORE"] = { ["EN"] = "Catching nine types of sturgeon will not be easy!"; }; | AJ4: =CONCATENATE("[""SUMMARY""] = { [""EN""] = """,J4,"""; }; ") -> ["SUMMARY"] = { ["EN"] = "Catch all 9 Sturgeon varieties"; }; | AK4: =IF(LEN(F4)>0,CONCATENATE("[""TITLE""] = { [""EN""] = """,F4,"""; }; "),"") -> ["TITLE"] = { ["EN"] = "Sturgeon-master"; }; | AL4: =CONCATENATE("};") -> };
A5: 1879110873 | B5: 4 | C5: The Salmon King | D5: Reputation | F5: the Complete Angler | I5: None | J5: Catch a 50-pound Salmon | K5: Only the most skilled - and lucky - fisher can make a catch of this size! | L5: 0 | O5: =CONCATENATE(R5,T5,U5,AL5," -- ",C5) -> [4] = {["ID"] = 1879110873; }; -- The Salmon King | P5: =CONCATENATE(R5,S5,V5,X5,Z5,AB5,AD5,AF5,AG5,AH5,AI5,AJ5,AK5,AL5) -> [4] = {["ID"] = 1879110873; ["SAVE_INDEX"] = 4; ["TYPE"] = 7; ["VXP"] = 0; ["LP"] = 0; ["REP"] = 0; ["FACTION"] = 1; ["TIER"] = 0; ["NAME"] = { ["EN"] = "The Salmon King"; }; ["LORE"] = { ["EN"] = "Only the most skilled - and lucky - fisher can make a catch of this size!"; }; ["SUMMARY"] = { ["EN"] = "Catch a 50-pound Salmon"; }; ["TITLE"] = { ["EN"] = "the Complete Angler"; }; }; | Q5: =ROW()-1 -> 4 | R5: =CONCATENATE(REPT(" ",3-LEN(Q5)),"[",Q5,"] = {") -> [4] = { | S5: =IF(LEN(A5)>0,CONCATENATE("[""ID""] = ",A5,"; ")," ") -> ["ID"] = 1879110873; | T5: =IF(LEN(A5)>0,CONCATENATE("[""ID""] = ",A5,"; "),"") -> ["ID"] = 1879110873; | U5: =IF(LEN(M5)>0,CONCATENATE("[""CAT_ID""] = ",M5,"; "),"") | V5: =IF(LEN(B5)>0,CONCATENATE("[""SAVE_INDEX""] = ",REPT(" ",1-LEN(B5)),B5,"; "),"") -> ["SAVE_INDEX"] = 4; | W5: =VLOOKUP(D5,Type!A$2:B$17,2,FALSE) -> 7 | X5: =CONCATENATE("[""TYPE""] = ",REPT(" ",2-LEN(W5)),W5,"; ") -> ["TYPE"] = 7; | Y5: =TEXT(E5,0) -> 0 | Z5: =CONCATENATE("[""VXP""] = ",REPT(" ",1-LEN(Y5)),TEXT(Y5,"0"),"; ") -> ["VXP"] = 0; | AA5: =TEXT(G5,0) -> 0 | AB5: =CONCATENATE("[""LP""] = ",REPT(" ",1-LEN(AA5)),TEXT(AA5,"0"),"; ") -> ["LP"] = 0; | AC5: =TEXT(H5,0) -> 0 | AD5: =CONCATENATE("[""REP""] = ",REPT(" ",1-LEN(AC5)),TEXT(AC5,"0"),"; ") -> ["REP"] = 0; | AE5: =VLOOKUP(I5,Faction!A$2:B$77,2,FALSE) -> 1 | AF5: =CONCATENATE("[""FACTION""] = ",TEXT(AE5,"0"),"; ") -> ["FACTION"] = 1; | AG5: =CONCATENATE("[""TIER""] = ",TEXT(L5,"0"),"; ") -> ["TIER"] = 0; | AH5: =CONCATENATE("[""NAME""] = { [""EN""] = """,C5,"""; }; ") -> ["NAME"] = { ["EN"] = "The Salmon King"; }; | AI5: =CONCATENATE("[""LORE""] = { [""EN""] = """,K5,"""; }; ") -> ["LORE"] = { ["EN"] = "Only the most skilled - and lucky - fisher can make a catch of this size!"; }; | AJ5: =CONCATENATE("[""SUMMARY""] = { [""EN""] = """,J5,"""; }; ") -> ["SUMMARY"] = { ["EN"] = "Catch a 50-pound Salmon"; }; | AK5: =IF(LEN(F5)>0,CONCATENATE("[""TITLE""] = { [""EN""] = """,F5,"""; }; "),"") -> ["TITLE"] = { ["EN"] = "the Complete Angler"; }; | AL5: =CONCATENATE("};") -> };
A6: 1879115023 | B6: 5 | C6: Trout-master | D6: Reputation | F6: Trout-master | I6: None | J6: Catch all 9 Trout varieties | K6: Find and catch all nine types of trout! | L6: 0 | O6: =CONCATENATE(R6,T6,U6,AL6," -- ",C6) -> [5] = {["ID"] = 1879115023; }; -- Trout-master | P6: =CONCATENATE(R6,S6,V6,X6,Z6,AB6,AD6,AF6,AG6,AH6,AI6,AJ6,AK6,AL6) -> [5] = {["ID"] = 1879115023; ["SAVE_INDEX"] = 5; ["TYPE"] = 7; ["VXP"] = 0; ["LP"] = 0; ["REP"] = 0; ["FACTION"] = 1; ["TIER"] = 0; ["NAME"] = { ["EN"] = "Trout-master"; }; ["LORE"] = { ["EN"] = "Find and catch all nine types of trout!"; }; ["SUMMARY"] = { ["EN"] = "Catch all 9 Trout varieties"; }; ["TITLE"] = { ["EN"] = "Trout-master"; }; }; | Q6: =ROW()-1 -> 5 | R6: =CONCATENATE(REPT(" ",3-LEN(Q6)),"[",Q6,"] = {") -> [5] = { | S6: =IF(LEN(A6)>0,CONCATENATE("[""ID""] = ",A6,"; ")," ") -> ["ID"] = 1879115023; | T6: =IF(LEN(A6)>0,CONCATENATE("[""ID""] = ",A6,"; "),"") -> ["ID"] = 1879115023; | U6: =IF(LEN(M6)>0,CONCATENATE("[""CAT_ID""] = ",M6,"; "),"") | V6: =IF(LEN(B6)>0,CONCATENATE("[""SAVE_INDEX""] = ",REPT(" ",1-LEN(B6)),B6,"; "),"") -> ["SAVE_INDEX"] = 5; | W6: =VLOOKUP(D6,Type!A$2:B$17,2,FALSE) -> 7 | X6: =CONCATENATE("[""TYPE""] = ",REPT(" ",2-LEN(W6)),W6,"; ") -> ["TYPE"] = 7; | Y6: =TEXT(E6,0) -> 0 | Z6: =CONCATENATE("[""VXP""] = ",REPT(" ",1-LEN(Y6)),TEXT(Y6,"0"),"; ") -> ["VXP"] = 0; | AA6: =TEXT(G6,0) -> 0 | AB6: =CONCATENATE("[""LP""] = ",REPT(" ",1-LEN(AA6)),TEXT(AA6,"0"),"; ") -> ["LP"] = 0; | AC6: =TEXT(H6,0) -> 0 | AD6: =CONCATENATE("[""REP""] = ",REPT(" ",1-LEN(AC6)),TEXT(AC6,"0"),"; ") -> ["REP"] = 0; | AE6: =VLOOKUP(I6,Faction!A$2:B$77,2,FALSE) -> 1 | AF6: =CONCATENATE("[""FACTION""] = ",TEXT(AE6,"0"),"; ") -> ["FACTION"] = 1; | AG6: =CONCATENATE("[""TIER""] = ",TEXT(L6,"0"),"; ") -> ["TIER"] = 0; | AH6: =CONCATENATE("[""NAME""] = { [""EN""] = """,C6,"""; }; ") -> ["NAME"] = { ["EN"] = "Trout-master"; }; | AI6: =CONCATENATE("[""LORE""] = { [""EN""] = """,K6,"""; }; ") -> ["LORE"] = { ["EN"] = "Find and catch all nine types of trout!"; }; | AJ6: =CONCATENATE("[""SUMMARY""] = { [""EN""] = """,J6,"""; }; ") -> ["SUMMARY"] = { ["EN"] = "Catch all 9 Trout varieties"; }; | AK6: =IF(LEN(F6)>0,CONCATENATE("[""TITLE""] = { [""EN""] = """,F6,"""; }; "),"") -> ["TITLE"] = { ["EN"] = "Trout-master"; }; | AL6: =CONCATENATE("};") -> };
A7: 1879364959 | B7: 6 | C7: Lake-master | D7: Reputation | F7: Lake-master | I7: None | J7: Catch all 20 fish varieties in Lake-town | K7: Find and catch all twenty types of eastern, freshwater fish! | L7: 0 | O7: =CONCATENATE(R7,T7,U7,AL7," -- ",C7) -> [6] = {["ID"] = 1879364959; }; -- Lake-master | P7: =CONCATENATE(R7,S7,V7,X7,Z7,AB7,AD7,AF7,AG7,AH7,AI7,AJ7,AK7,AL7) -> [6] = {["ID"] = 1879364959; ["SAVE_INDEX"] = 6; ["TYPE"] = 7; ["VXP"] = 0; ["LP"] = 0; ["REP"] = 0; ["FACTION"] = 1; ["TIER"] = 0; ["NAME"] = { ["EN"] = "Lake-master"; }; ["LORE"] = { ["EN"] = "Find and catch all twenty types of eastern, freshwater fish!"; }; ["SUMMARY"] = { ["EN"] = "Catch all 20 fish varieties in Lake-town"; }; ["TITLE"] = { ["EN"] = "Lake-master"; }; }; | Q7: =ROW()-1 -> 6 | R7: =CONCATENATE(REPT(" ",3-LEN(Q7)),"[",Q7,"] = {") -> [6] = { | S7: =IF(LEN(A7)>0,CONCATENATE("[""ID""] = ",A7,"; ")," ") -> ["ID"] = 1879364959; | T7: =IF(LEN(A7)>0,CONCATENATE("[""ID""] = ",A7,"; "),"") -> ["ID"] = 1879364959; | U7: =IF(LEN(M7)>0,CONCATENATE("[""CAT_ID""] = ",M7,"; "),"") | V7: =IF(LEN(B7)>0,CONCATENATE("[""SAVE_INDEX""] = ",REPT(" ",1-LEN(B7)),B7,"; "),"") -> ["SAVE_INDEX"] = 6; | W7: =VLOOKUP(D7,Type!A$2:B$17,2,FALSE) -> 7 | X7: =CONCATENATE("[""TYPE""] = ",REPT(" ",2-LEN(W7)),W7,"; ") -> ["TYPE"] = 7; | Y7: =TEXT(E7,0) -> 0 | Z7: =CONCATENATE("[""VXP""] = ",REPT(" ",1-LEN(Y7)),TEXT(Y7,"0"),"; ") -> ["VXP"] = 0; | AA7: =TEXT(G7,0) -> 0 | AB7: =CONCATENATE("[""LP""] = ",REPT(" ",1-LEN(AA7)),TEXT(AA7,"0"),"; ") -> ["LP"] = 0; | AC7: =TEXT(H7,0) -> 0 | AD7: =CONCATENATE("[""REP""] = ",REPT(" ",1-LEN(AC7)),TEXT(AC7,"0"),"; ") -> ["REP"] = 0; | AE7: =VLOOKUP(I7,Faction!A$2:B$77,2,FALSE) -> 1 | AF7: =CONCATENATE("[""FACTION""] = ",TEXT(AE7,"0"),"; ") -> ["FACTION"] = 1; | AG7: =CONCATENATE("[""TIER""] = ",TEXT(L7,"0"),"; ") -> ["TIER"] = 0; | AH7: =CONCATENATE("[""NAME""] = { [""EN""] = """,C7,"""; }; ") -> ["NAME"] = { ["EN"] = "Lake-master"; }; | AI7: =CONCATENATE("[""LORE""] = { [""EN""] = """,K7,"""; }; ") -> ["LORE"] = { ["EN"] = "Find and catch all twenty types of eastern, freshwater fish!"; }; | AJ7: =CONCATENATE("[""SUMMARY""] = { [""EN""] = """,J7,"""; }; ") -> ["SUMMARY"] = { ["EN"] = "Catch all 20 fish varieties in Lake-town"; }; | AK7: =IF(LEN(F7)>0,CONCATENATE("[""TITLE""] = { [""EN""] = """,F7,"""; }; "),"") -> ["TITLE"] = { ["EN"] = "Lake-master"; }; | AL7: =CONCATENATE("};") -> };

Sheet Birding
A1: ID | B1: Save Index | C1: Name | D1: TYPE | E1: VXP | F1: Title | G1: LP | H1: REP | I1: FACTION | J1: SUMMARY | K1: DESC | L1: TIER | M1: Category ID | N1: Output parts | O1: Tier code | P1: Minimal | Q1: Complete | R1: QuestNumber | S1: Index | T1: ID | U1: ID (short) | V1: Category ID | W1: Save Index | X1: TYPE_INT | Y1: Type | Z1: VXP_NUM | AA1: VXP | AB1: LP_NUM | AC1: LP | AD1: REP_NUM | AE1: REP | AF1: FACTION_INT | AG1: FACTION | AH1: TIER | AI1: NAME | AJ1: LORE | AK1: SUMMARY | AL1: TITLE | AM1: End
C2: Eriador | D2: Category | M2: 320 | O2: =IF(AND(A2>0,L2>0),CONCATENATE("[",A2,"] = ",L2,", // ",C2),"") | P2: =CONCATENATE(S2,U2,V2,AH2,AM2," -- ",C2) -> [1] = {["CAT_ID"] = 320; }; -- Eriador | Q2: =CONCATENATE(S2,T2,W2,Y2,AA2,AC2,AE2,AG2,AH2,AI2,AJ2,AK2,AL2,AM2) -> #N/A | R2: =ROW()-1 -> 1 | S2: =CONCATENATE(REPT(" ",3-LEN(R2)),"[",R2,"] = {") -> [1] = { | T2: =IF(LEN(A2)>0,CONCATENATE("[""ID""] = ",A2,"; ")," ") | U2: =IF(LEN(A2)>0,CONCATENATE("[""ID""] = ",A2,"; "),"") | V2: =IF(LEN(M2)>0,CONCATENATE("[""CAT_ID""] = ",M2,"; "),"") -> ["CAT_ID"] = 320; | W2: =IF(LEN(B2)>0,CONCATENATE("[""SAVE_INDEX""] = ",REPT(" ",1-LEN(B2)),B2,"; "),"") | X2: =VLOOKUP(D2,Type!A$2:B$17,2,FALSE) -> 14 | Y2: =CONCATENATE("[""TYPE""] = ",REPT(" ",2-LEN(X2)),X2,"; ") -> ["TYPE"] = 14; | Z2: =TEXT(E2,0) -> 0 | AA2: =CONCATENATE("[""VXP""] = ",REPT(" ",1-LEN(Z2)),TEXT(Z2,"0"),"; ") -> ["VXP"] = 0; | AB2: =TEXT(G2,0) -> 0 | AC2: =CONCATENATE("[""LP""] = ",REPT(" ",1-LEN(AB2)),TEXT(AB2,"0"),"; ") -> ["LP"] = 0; | AD2: =TEXT(H2,0) -> 0 | AE2: =CONCATENATE("[""REP""] = ",REPT(" ",1-LEN(AD2)),TEXT(AD2,"0"),"; ") -> ["REP"] = 0; | AF2: =VLOOKUP(I2,Faction!A$2:B$77,2,FALSE) -> #N/A | AG2: =CONCATENATE("[""FACTION""] = ",TEXT(AF2,"0"),"; ") -> #N/A | AH2: =IF(L2>0,CONCATENATE("[""TIER""] = ",TEXT(L2,"0"),"; "),"") | AI2: =CONCATENATE("[""NAME""] = { [""EN""] = """,C2,"""; }; ") -> ["NAME"] = { ["EN"] = "Eriador"; }; | AJ2: =CONCATENATE("[""LORE""] = { [""EN""] = """,K2,"""; }; ") -> ["LORE"] = { ["EN"] = ""; }; | AK2: =CONCATENATE("[""SUMMARY""] = { [""EN""] = """,J2,"""; }; ") -> ["SUMMARY"] = { ["EN"] = ""; }; | AL2: =IF(LEN(F2)>0,CONCATENATE("[""TITLE""] = { [""EN""] = """,F2,"""; }; "),"") | AM2: =CONCATENATE("};") -> };
A3: 1879490678 | C3: All the Birds of Bree-land | I3: None | L3: 0 | O3: =IF(AND(A3>0,L3>0),CONCATENATE("[",A3,"] = ",L3,", // ",C3),"") | P3: =CONCATENATE(S3,U3,V3,AH3,AM3," -- ",C3) -> [2] = {["ID"] = 1879490678; }; -- All the Birds of Bree-land | Q3: =CONCATENATE(S3,T3,W3,Y3,AA3,AC3,AE3,AG3,AH3,AI3,AJ3,AK3,AL3,AM3) -> #N/A | R3: =ROW()-1 -> 2 | S3: =CONCATENATE(REPT(" ",3-LEN(R3)),"[",R3,"] = {") -> [2] = { | T3: =IF(LEN(A3)>0,CONCATENATE("[""ID""] = ",A3,"; ")," ") -> ["ID"] = 1879490678; | U3: =IF(LEN(A3)>0,CONCATENATE("[""ID""] = ",A3,"; "),"") -> ["ID"] = 1879490678; | V3: =IF(LEN(M3)>0,CONCATENATE("[""CAT_ID""] = ",M3,"; "),"") | W3: =IF(LEN(B3)>0,CONCATENATE("[""SAVE_INDEX""] = ",REPT(" ",1-LEN(B3)),B3,"; "),"") | X3: =VLOOKUP(D3,Type!A$2:B$17,2,FALSE) -> #N/A | Y3: =CONCATENATE("[""TYPE""] = ",REPT(" ",2-LEN(X3)),X3,"; ") -> #N/A | Z3: =TEXT(E3,0) -> 0 | AA3: =CONCATENATE("[""VXP""] = ",REPT(" ",1-LEN(Z3)),TEXT(Z3,"0"),"; ") -> ["VXP"] = 0; | AB3: =TEXT(G3,0) -> 0 | AC3: =CONCATENATE("[""LP""] = ",REPT(" ",1-LEN(AB3)),TEXT(AB3,"0"),"; ") -> ["LP"] = 0; | AD3: =TEXT(H3,0) -> 0 | AE3: =CONCATENATE("[""REP""] = ",REPT(" ",1-LEN(AD3)),TEXT(AD3,"0"),"; ") -> ["REP"] = 0; | AF3: =VLOOKUP(I3,Faction!A$2:B$77,2,FALSE) -> 1 | AG3: =CONCATENATE("[""FACTION""] = ",TEXT(AF3,"0"),"; ") -> ["FACTION"] = 1; | AH3: =IF(L3>0,CONCATENATE("[""TIER""] = ",TEXT(L3,"0"),"; "),"") | AI3: =CONCATENATE("[""NAME""] = { [""EN""] = """,C3,"""; }; ") -> ["NAME"] = { ["EN"] = "All the Birds of Bree-land"; }; | AJ3: =CONCATENATE("[""LORE""] = { [""EN""] = """,K3,"""; }; ") -> ["LORE"] = { ["EN"] = ""; }; | AK3: =CONCATENATE("[""SUMMARY""] = { [""EN""] = """,J3,"""; }; ") -> ["SUMMARY"] = { ["EN"] = ""; }; | AL3: =IF(LEN(F3)>0,CONCATENATE("[""TITLE""] = { [""EN""] = """,F3,"""; }; "),"") | AM3: =CONCATENATE("};") -> };
A4: 1879490611 | C4: Birds of Bree-land: Common and Uncommon | I4: None | L4: 1 | O4: =IF(AND(A4>0,L4>0),CONCATENATE("[",A4,"] = ",L4,", // ",C4),"") -> [1879490611] = 1, // Birds of Bree-land: Common and Uncommon | P4: =CONCATENATE(S4,U4,V4,AH4,AM4," -- ",C4) -> [3] = {["ID"] = 1879490611; ["TIER"] = 1; }; -- Birds of Bree-land: Common and Uncommon | Q4: =CONCATENATE(S4,T4,W4,Y4,AA4,AC4,AE4,AG4,AH4,AI4,AJ4,AK4,AL4,AM4) -> #N/A | R4: =ROW()-1 -> 3 | S4: =CONCATENATE(REPT(" ",3-LEN(R4)),"[",R4,"] = {") -> [3] = { | T4: =IF(LEN(A4)>0,CONCATENATE("[""ID""] = ",A4,"; ")," ") -> ["ID"] = 1879490611; | U4: =IF(LEN(A4)>0,CONCATENATE("[""ID""] = ",A4,"; "),"") -> ["ID"] = 1879490611; | V4: =IF(LEN(M4)>0,CONCATENATE("[""CAT_ID""] = ",M4,"; "),"") | W4: =IF(LEN(B4)>0,CONCATENATE("[""SAVE_INDEX""] = ",REPT(" ",1-LEN(B4)),B4,"; "),"") | X4: =VLOOKUP(D4,Type!A$2:B$17,2,FALSE) -> #N/A | Y4: =CONCATENATE("[""TYPE""] = ",REPT(" ",2-LEN(X4)),X4,"; ") -> #N/A | Z4: =TEXT(E4,0) -> 0 | AA4: =CONCATENATE("[""VXP""] = ",REPT(" ",1-LEN(Z4)),TEXT(Z4,"0"),"; ") -> ["VXP"] = 0; | AB4: =TEXT(G4,0) -> 0 | AC4: =CONCATENATE("[""LP""] = ",REPT(" ",1-LEN(AB4)),TEXT(AB4,"0"),"; ") -> ["LP"] = 0; | AD4: =TEXT(H4,0) -> 0 | AE4: =CONCATENATE("[""REP""] = ",REPT(" ",1-LEN(AD4)),TEXT(AD4,"0"),"; ") -> ["REP"] = 0; | AF4: =VLOOKUP(I4,Faction!A$2:B$77,2,FALSE) -> 1 | AG4: =CONCATENATE("[""FACTION""] = ",TEXT(AF4,"0"),"; ") -> ["FACTION"] = 1; | AH4: =IF(L4>0,CONCATENATE("[""TIER""] = ",TEXT(L4,"0"),"; "),"") -> ["TIER"] = 1; | AI4: =CONCATENATE("[""NAME""] = { [""EN""] = """,C4,"""; }; ") -> ["NAME"] = { ["EN"] = "Birds of Bree-land: Common and Uncommon"; }; | AJ4: =CONCATENATE("[""LORE""] = { [""EN""] = """,K4,"""; }; ") -> ["LORE"] = { ["EN"] = ""; }; | AK4: =CONCATENATE("[""SUMMARY""] = { [""EN""] = """,J4,"""; }; ") -> ["SUMMARY"] = { ["EN"] = ""; }; | AL4: =IF(LEN(F4)>0,CONCATENATE("[""TITLE""] = { [""EN""] = """,F4,"""; }; "),"") | AM4: =CONCATENATE("};") -> };
A5: 1879490469 | C5: Birds of Bree-land: Rare | I5: None | L5: 1 | O5: =IF(AND(A5>0,L5>0),CONCATENATE("[",A5,"] = ",L5,", // ",C5),"") -> [1879490469] = 1, // Birds of Bree-land: Rare | P5: =CONCATENATE(S5,U5,V5,AH5,AM5," -- ",C5) -> [4] = {["ID"] = 1879490469; ["TIER"] = 1; }; -- Birds of Bree-land: Rare | Q5: =CONCATENATE(S5,T5,W5,Y5,AA5,AC5,AE5,AG5,AH5,AI5,AJ5,AK5,AL5,AM5) -> #N/A | R5: =ROW()-1 -> 4 | S5: =CONCATENATE(REPT(" ",3-LEN(R5)),"[",R5,"] = {") -> [4] = { | T5: =IF(LEN(A5)>0,CONCATENATE("[""ID""] = ",A5,"; ")," ") -> ["ID"] = 1879490469; | U5: =IF(LEN(A5)>0,CONCATENATE("[""ID""] = ",A5,"; "),"") -> ["ID"] = 1879490469; | V5: =IF(LEN(M5)>0,CONCATENATE("[""CAT_ID""] = ",M5,"; "),"") | W5: =IF(LEN(B5)>0,CONCATENATE("[""SAVE_INDEX""] = ",REPT(" ",1-LEN(B5)),B5,"; "),"") | X5: =VLOOKUP(D5,Type!A$2:B$17,2,FALSE) -> #N/A | Y5: =CONCATENATE("[""TYPE""] = ",REPT(" ",2-LEN(X5)),X5,"; ") -> #N/A | Z5: =TEXT(E5,0) -> 0 | AA5: =CONCATENATE("[""VXP""] = ",REPT(" ",1-LEN(Z5)),TEXT(Z5,"0"),"; ") -> ["VXP"] = 0; | AB5: =TEXT(G5,0) -> 0 | AC5: =CONCATENATE("[""LP""] = ",REPT(" ",1-LEN(AB5)),TEXT(AB5,"0"),"; ") -> ["LP"] = 0; | AD5: =TEXT(H5,0) -> 0 | AE5: =CONCATENATE("[""REP""] = ",REPT(" ",1-LEN(AD5)),TEXT(AD5,"0"),"; ") -> ["REP"] = 0; | AF5: =VLOOKUP(I5,Faction!A$2:B$77,2,FALSE) -> 1 | AG5: =CONCATENATE("[""FACTION""] = ",TEXT(AF5,"0"),"; ") -> ["FACTION"] = 1; | AH5: =IF(L5>0,CONCATENATE("[""TIER""] = ",TEXT(L5,"0"),"; "),"") -> ["TIER"] = 1; | AI5: =CONCATENATE("[""NAME""] = { [""EN""] = """,C5,"""; }; ") -> ["NAME"] = { ["EN"] = "Birds of Bree-land: Rare"; }; | AJ5: =CONCATENATE("[""LORE""] = { [""EN""] = """,K5,"""; }; ") -> ["LORE"] = { ["EN"] = ""; }; | AK5: =CONCATENATE("[""SUMMARY""] = { [""EN""] = """,J5,"""; }; ") -> ["SUMMARY"] = { ["EN"] = ""; }; | AL5: =IF(LEN(F5)>0,CONCATENATE("[""TITLE""] = { [""EN""] = """,F5,"""; }; "),"") | AM5: =CONCATENATE("};") -> };
A6: 1879490610 | C6: The Rarest Bird in Bree-land | I6: None | L6: 1 | O6: =IF(AND(A6>0,L6>0),CONCATENATE("[",A6,"] = ",L6,", // ",C6),"") -> [1879490610] = 1, // The Rarest Bird in Bree-land | P6: =CONCATENATE(S6,U6,V6,AH6,AM6," -- ",C6) -> [5] = {["ID"] = 1879490610; ["TIER"] = 1; }; -- The Rarest Bird in Bree-land | Q6: =CONCATENATE(S6,T6,W6,Y6,AA6,AC6,AE6,AG6,AH6,AI6,AJ6,AK6,AL6,AM6) -> #N/A | R6: =ROW()-1 -> 5 | S6: =CONCATENATE(REPT(" ",3-LEN(R6)),"[",R6,"] = {") -> [5] = { | T6: =IF(LEN(A6)>0,CONCATENATE("[""ID""] = ",A6,"; ")," ") -> ["ID"] = 1879490610; | U6: =IF(LEN(A6)>0,CONCATENATE("[""ID""] = ",A6,"; "),"") -> ["ID"] = 1879490610; | V6: =IF(LEN(M6)>0,CONCATENATE("[""CAT_ID""] = ",M6,"; "),"") | W6: =IF(LEN(B6)>0,CONCATENATE("[""SAVE_INDEX""] = ",REPT(" ",1-LEN(B6)),B6,"; "),"") | X6: =VLOOKUP(D6,Type!A$2:B$17,2,FALSE) -> #N/A | Y6: =CONCATENATE("[""TYPE""] = ",REPT(" ",2-LEN(X6)),X6,"; ") -> #N/A | Z6: =TEXT(E6,0) -> 0 | AA6: =CONCATENATE("[""VXP""] = ",REPT(" ",1-LEN(Z6)),TEXT(Z6,"0"),"; ") -> ["VXP"] = 0; | AB6: =TEXT(G6,0) -> 0 | AC6: =CONCATENATE("[""LP""] = ",REPT(" ",1-LEN(AB6)),TEXT(AB6,"0"),"; ") -> ["LP"] = 0; | AD6: =TEXT(H6,0) -> 0 | AE6: =CONCATENATE("[""REP""] = ",REPT(" ",1-LEN(AD6)),TEXT(AD6,"0"),"; ") -> ["REP"] = 0; | AF6: =VLOOKUP(I6,Faction!A$2:B$77,2,FALSE) -> 1 | AG6: =CONCATENATE("[""FACTION""] = ",TEXT(AF6,"0"),"; ") -> ["FACTION"] = 1; | AH6: =IF(L6>0,CONCATENATE("[""TIER""] = ",TEXT(L6,"0"),"; "),"") -> ["TIER"] = 1; | AI6: =CONCATENATE("[""NAME""] = { [""EN""] = """,C6,"""; }; ") -> ["NAME"] = { ["EN"] = "The Rarest Bird in Bree-land"; }; | AJ6: =CONCATENATE("[""LORE""] = { [""EN""] = """,K6,"""; }; ") -> ["LORE"] = { ["EN"] = ""; }; | AK6: =CONCATENATE("[""SUMMARY""] = { [""EN""] = """,J6,"""; }; ") -> ["SUMMARY"] = { ["EN"] = ""; }; | AL6: =IF(LEN(F6)>0,CONCATENATE("[""TITLE""] = { [""EN""] = """,F6,"""; }; "),"") | AM6: =CONCATENATE("};") -> };
A7: 1879490682 | C7: All the Birds of the Shire | I7: None | L7: 0 | O7: =IF(AND(A7>0,L7>0),CONCATENATE("[",A7,"] = ",L7,", // ",C7),"") | P7: =CONCATENATE(S7,U7,V7,AH7,AM7," -- ",C7) -> [6] = {["ID"] = 1879490682; }; -- All the Birds of the Shire | Q7: =CONCATENATE(S7,T7,W7,Y7,AA7,AC7,AE7,AG7,AH7,AI7,AJ7,AK7,AL7,AM7) -> #N/A | R7: =ROW()-1 -> 6 | S7: =CONCATENATE(REPT(" ",3-LEN(R7)),"[",R7,"] = {") -> [6] = { | T7: =IF(LEN(A7)>0,CONCATENATE("[""ID""] = ",A7,"; ")," ") -> ["ID"] = 1879490682; | U7: =IF(LEN(A7)>0,CONCATENATE("[""ID""] = ",A7,"; "),"") -> ["ID"] = 1879490682; | V7: =IF(LEN(M7)>0,CONCATENATE("[""CAT_ID""] = ",M7,"; "),"") | W7: =IF(LEN(B7)>0,CONCATENATE("[""SAVE_INDEX""] = ",REPT(" ",1-LEN(B7)),B7,"; "),"") | X7: =VLOOKUP(D7,Type!A$2:B$17,2,FALSE) -> #N/A | Y7: =CONCATENATE("[""TYPE""] = ",REPT(" ",2-LEN(X7)),X7,"; ") -> #N/A | Z7: =TEXT(E7,0) -> 0 | AA7: =CONCATENATE("[""VXP""] = ",REPT(" ",1-LEN(Z7)),TEXT(Z7,"0"),"; ") -> ["VXP"] = 0; | AB7: =TEXT(G7,0) -> 0 | AC7: =CONCATENATE("[""LP""] = ",REPT(" ",1-LEN(AB7)),TEXT(AB7,"0"),"; ") -> ["LP"] = 0; | AD7: =TEXT(H7,0) -> 0 | AE7: =CONCATENATE("[""REP""] = ",REPT(" ",1-LEN(AD7)),TEXT(AD7,"0"),"; ") -> ["REP"] = 0; | AF7: =VLOOKUP(I7,Faction!A$2:B$77,2,FALSE) -> 1 | AG7: =CONCATENATE("[""FACTION""] = ",TEXT(AF7,"0"),"; ") -> ["FACTION"] = 1; | AH7: =IF(L7>0,CONCATENATE("[""TIER""] = ",TEXT(L7,"0"),"; "),"") | AI7: =CONCATENATE("[""NAME""] = { [""EN""] = """,C7,"""; }; ") -> ["NAME"] = { ["EN"] = "All the Birds of the Shire"; }; | AJ7: =CONCATENATE("[""LORE""] = { [""EN""] = """,K7,"""; }; ") -> ["LORE"] = { ["EN"] = ""; }; | AK7: =CONCATENATE("[""SUMMARY""] = { [""EN""] = """,J7,"""; }; ") -> ["SUMMARY"] = { ["EN"] = ""; }; | AL7: =IF(LEN(F7)>0,CONCATENATE("[""TITLE""] = { [""EN""] = """,F7,"""; }; "),"") | AM7: =CONCATENATE("};") -> };
A8: 1879490617 | C8: Birds of The Shire: Common and Uncommon | I8: None | L8: 1 | O8: =IF(AND(A8>0,L8>0),CONCATENATE("[",A8,"] = ",L8,", // ",C8),"") -> [1879490617] = 1, // Birds of The Shire: Common and Uncommon | P8: =CONCATENATE(S8,U8,V8,AH8,AM8," -- ",C8) -> [7] = {["ID"] = 1879490617; ["TIER"] = 1; }; -- Birds of The Shire: Common and Uncommon | Q8: =CONCATENATE(S8,T8,W8,Y8,AA8,AC8,AE8,AG8,AH8,AI8,AJ8,AK8,AL8,AM8) -> #N/A | R8: =ROW()-1 -> 7 | S8: =CONCATENATE(REPT(" ",3-LEN(R8)),"[",R8,"] = {") -> [7] = { | T8: =IF(LEN(A8)>0,CONCATENATE("[""ID""] = ",A8,"; ")," ") -> ["ID"] = 1879490617; | U8: =IF(LEN(A8)>0,CONCATENATE("[""ID""] = ",A8,"; "),"") -> ["ID"] = 1879490617; | V8: =IF(LEN(M8)>0,CONCATENATE("[""CAT_ID""] = ",M8,"; "),"") | W8: =IF(LEN(B8)>0,CONCATENATE("[""SAVE_INDEX""] = ",REPT(" ",1-LEN(B8)),B8,"; "),"") | X8: =VLOOKUP(D8,Type!A$2:B$17,2,FALSE) -> #N/A | Y8: =CONCATENATE("[""TYPE""] = ",REPT(" ",2-LEN(X8)),X8,"; ") -> #N/A | Z8: =TEXT(E8,0) -> 0 | AA8: =CONCATENATE("[""VXP""] = ",REPT(" ",1-LEN(Z8)),TEXT(Z8,"0"),"; ") -> ["VXP"] = 0; | AB8: =TEXT(G8,0) -> 0 | AC8: =CONCATENATE("[""LP""] = ",REPT(" ",1-LEN(AB8)),TEXT(AB8,"0"),"; ") -> ["LP"] = 0; | AD8: =TEXT(H8,0) -> 0 | AE8: =CONCATENATE("[""REP""] = ",REPT(" ",1-LEN(AD8)),TEXT(AD8,"0"),"; ") -> ["REP"] = 0; | AF8: =VLOOKUP(I8,Faction!A$2:B$77,2,FALSE) -> 1 | AG8: =CONCATENATE("[""FACTION""] = ",TEXT(AF8,"0"),"; ") -> ["FACTION"] = 1; | AH8: =IF(L8>0,CONCATENATE("[""TIER""] = ",TEXT(L8,"0"),"; "),"") -> ["TIER"] = 1; | AI8: =CONCATENATE("[""NAME""] = { [""EN""] = """,C8,"""; }; ") -> ["NAME"] = { ["EN"] = "Birds of The Shire: Common and Uncommon"; }; | AJ8: =CONCATENATE("[""LORE""] = { [""EN""] = """,K8,"""; }; ") -> ["LORE"] = { ["EN"] = ""; }; | AK8: =CONCATENATE("[""SUMMARY""] = { [""EN""] = """,J8,"""; }; ") -> ["SUMMARY"] = { ["EN"] = ""; }; | AL8: =IF(LEN(F8)>0,CONCATENATE("[""TITLE""] = { [""EN""] = """,F8,"""; }; "),"") | AM8: =CONCATENATE("};") -> };
A9: 1879490640 | C9: Birds of The Shire: Rare | L9: 1 | O9: =IF(AND(A9>0,L9>0),CONCATENATE("[",A9,"] = ",L9,", // ",C9),"") -> [1879490640] = 1, // Birds of The Shire: Rare | P9: =CONCATENATE(S9,U9,V9,AH9,AM9," -- ",C9) -> [8] = {["ID"] = 1879490640; ["TIER"] = 1; }; -- Birds of The Shire: Rare | Q9: =CONCATENATE(S9,T9,W9,Y9,AA9,AC9,AE9,AG9,AH9,AI9,AJ9,AK9,AL9,AM9) -> #N/A | R9: =ROW()-1 -> 8 | S9: =CONCATENATE(REPT(" ",3-LEN(R9)),"[",R9,"] = {") -> [8] = { | T9: =IF(LEN(A9)>0,CONCATENATE("[""ID""] = ",A9,"; ")," ") -> ["ID"] = 1879490640; | U9: =IF(LEN(A9)>0,CONCATENATE("[""ID""] = ",A9,"; "),"") -> ["ID"] = 1879490640; | V9: =IF(LEN(M9)>0,CONCATENATE("[""CAT_ID""] = ",M9,"; "),"") | W9: =IF(LEN(B9)>0,CONCATENATE("[""SAVE_INDEX""] = ",REPT(" ",1-LEN(B9)),B9,"; "),"") | X9: =VLOOKUP(D9,Type!A$2:B$17,2,FALSE) -> #N/A | Y9: =CONCATENATE("[""TYPE""] = ",REPT(" ",2-LEN(X9)),X9,"; ") -> #N/A | Z9: =TEXT(E9,0) -> 0 | AA9: =CONCATENATE("[""VXP""] = ",REPT(" ",1-LEN(Z9)),TEXT(Z9,"0"),"; ") -> ["VXP"] = 0; | AB9: =TEXT(G9,0) -> 0 | AC9: =CONCATENATE("[""LP""] = ",REPT(" ",1-LEN(AB9)),TEXT(AB9,"0"),"; ") -> ["LP"] = 0; | AD9: =TEXT(H9,0) -> 0 | AE9: =CONCATENATE("[""REP""] = ",REPT(" ",1-LEN(AD9)),TEXT(AD9,"0"),"; ") -> ["REP"] = 0; | AF9: =VLOOKUP(I9,Faction!A$2:B$77,2,FALSE) -> #N/A | AG9: =CONCATENATE("[""FACTION""] = ",TEXT(AF9,"0"),"; ") -> #N/A | AH9: =IF(L9>0,CONCATENATE("[""TIER""] = ",TEXT(L9,"0"),"; "),"") -> ["TIER"] = 1; | AI9: =CONCATENATE("[""NAME""] = { [""EN""] = """,C9,"""; }; ") -> ["NAME"] = { ["EN"] = "Birds of The Shire: Rare"; }; | AJ9: =CONCATENATE("[""LORE""] = { [""EN""] = """,K9,"""; }; ") -> ["LORE"] = { ["EN"] = ""; }; | AK9: =CONCATENATE("[""SUMMARY""] = { [""EN""] = """,J9,"""; }; ") -> ["SUMMARY"] = { ["EN"] = ""; }; | AL9: =IF(LEN(F9)>0,CONCATENATE("[""TITLE""] = { [""EN""] = """,F9,"""; }; "),"") | AM9: =CONCATENATE("};") -> };
A10: 1879490622 | C10: The Rarest Bird in The Shire | L10: 1 | O10: =IF(AND(A10>0,L10>0),CONCATENATE("[",A10,"] = ",L10,", // ",C10),"") -> [1879490622] = 1, // The Rarest Bird in The Shire | P10: =CONCATENATE(S10,U10,V10,AH10,AM10," -- ",C10) -> [9] = {["ID"] = 1879490622; ["TIER"] = 1; }; -- The Rarest Bird in The Shire | Q10: =CONCATENATE(S10,T10,W10,Y10,AA10,AC10,AE10,AG10,AH10,AI10,AJ10,AK10,AL10,AM10) -> #N/A | R10: =ROW()-1 -> 9 | S10: =CONCATENATE(REPT(" ",3-LEN(R10)),"[",R10,"] = {") -> [9] = { | T10: =IF(LEN(A10)>0,CONCATENATE("[""ID""] = ",A10,"; ")," ") -> ["ID"] = 1879490622; | U10: =IF(LEN(A10)>0,CONCATENATE("[""ID""] = ",A10,"; "),"") -> ["ID"] = 1879490622; | V10: =IF(LEN(M10)>0,CONCATENATE("[""CAT_ID""] = ",M10,"; "),"") | W10: =IF(LEN(B10)>0,CONCATENATE("[""SAVE_INDEX""] = ",REPT(" ",1-LEN(B10)),B10,"; "),"") | X10: =VLOOKUP(D10,Type!A$2:B$17,2,FALSE) -> #N/A | Y10: =CONCATENATE("[""TYPE""] = ",REPT(" ",2-LEN(X10)),X10,"; ") -> #N/A | Z10: =TEXT(E10,0) -> 0 | AA10: =CONCATENATE("[""VXP""] = ",REPT(" ",1-LEN(Z10)),TEXT(Z10,"0"),"; ") -> ["VXP"] = 0; | AB10: =TEXT(G10,0) -> 0 | AC10: =CONCATENATE("[""LP""] = ",REPT(" ",1-LEN(AB10)),TEXT(AB10,"0"),"; ") -> ["LP"] = 0; | AD10: =TEXT(H10,0) -> 0 | AE10: =CONCATENATE("[""REP""] = ",REPT(" ",1-LEN(AD10)),TEXT(AD10,"0"),"; ") -> ["REP"] = 0; | AF10: =VLOOKUP(I10,Faction!A$2:B$77,2,FALSE) -> #N/A | AG10: =CONCATENATE("[""FACTION""] = ",TEXT(AF10,"0"),"; ") -> #N/A | AH10: =IF(L10>0,CONCATENATE("[""TIER""] = ",TEXT(L10,"0"),"; "),"") -> ["TIER"] = 1; | AI10: =CONCATENATE("[""NAME""] = { [""EN""] = """,C10,"""; }; ") -> ["NAME"] = { ["EN"] = "The Rarest Bird in The Shire"; }; | AJ10: =CONCATENATE("[""LORE""] = { [""EN""] = """,K10,"""; }; ") -> ["LORE"] = { ["EN"] = ""; }; | AK10: =CONCATENATE("[""SUMMARY""] = { [""EN""] = """,J10,"""; }; ") -> ["SUMMARY"] = { ["EN"] = ""; }; | AL10: =IF(LEN(F10)>0,CONCATENATE("[""TITLE""] = { [""EN""] = """,F10,"""; }; "),"") | AM10: =CONCATENATE("};") -> };
A11: 1879490671 | C11: All the Birds of Ered Luin | L11: 0 | O11: =IF(AND(A11>0,L11>0),CONCATENATE("[",A11,"] = ",L11,", // ",C11),"") | P11: =CONCATENATE(S11,U11,V11,AH11,AM11," -- ",C11) -> [10] = {["ID"] = 1879490671; }; -- All the Birds of Ered Luin | Q11: =CONCATENATE(S11,T11,W11,Y11,AA11,AC11,AE11,AG11,AH11,AI11,AJ11,AK11,AL11,AM11) -> #N/A | R11: =ROW()-1 -> 10 | S11: =CONCATENATE(REPT(" ",3-LEN(R11)),"[",R11,"] = {") -> [10] = { | T11: =IF(LEN(A11)>0,CONCATENATE("[""ID""] = ",A11,"; ")," ") -> ["ID"] = 1879490671; | U11: =IF(LEN(A11)>0,CONCATENATE("[""ID""] = ",A11,"; "),"") -> ["ID"] = 1879490671; | V11: =IF(LEN(M11)>0,CONCATENATE("[""CAT_ID""] = ",M11,"; "),"") | W11: =IF(LEN(B11)>0,CONCATENATE("[""SAVE_INDEX""] = ",REPT(" ",1-LEN(B11)),B11,"; "),"") | X11: =VLOOKUP(D11,Type!A$2:B$17,2,FALSE) -> #N/A | Y11: =CONCATENATE("[""TYPE""] = ",REPT(" ",2-LEN(X11)),X11,"; ") -> #N/A | Z11: =TEXT(E11,0) -> 0 | AA11: =CONCATENATE("[""VXP""] = ",REPT(" ",1-LEN(Z11)),TEXT(Z11,"0"),"; ") -> ["VXP"] = 0; | AB11: =TEXT(G11,0) -> 0 | AC11: =CONCATENATE("[""LP""] = ",REPT(" ",1-LEN(AB11)),TEXT(AB11,"0"),"; ") -> ["LP"] = 0; | AD11: =TEXT(H11,0) -> 0 | AE11: =CONCATENATE("[""REP""] = ",REPT(" ",1-LEN(AD11)),TEXT(AD11,"0"),"; ") -> ["REP"] = 0; | AF11: =VLOOKUP(I11,Faction!A$2:B$77,2,FALSE) -> #N/A | AG11: =CONCATENATE("[""FACTION""] = ",TEXT(AF11,"0"),"; ") -> #N/A | AH11: =IF(L11>0,CONCATENATE("[""TIER""] = ",TEXT(L11,"0"),"; "),"") | AI11: =CONCATENATE("[""NAME""] = { [""EN""] = """,C11,"""; }; ") -> ["NAME"] = { ["EN"] = "All the Birds of Ered Luin"; }; | AJ11: =CONCATENATE("[""LORE""] = { [""EN""] = """,K11,"""; }; ") -> ["LORE"] = { ["EN"] = ""; }; | AK11: =CONCATENATE("[""SUMMARY""] = { [""EN""] = """,J11,"""; }; ") -> ["SUMMARY"] = { ["EN"] = ""; }; | AL11: =IF(LEN(F11)>0,CONCATENATE("[""TITLE""] = { [""EN""] = """,F11,"""; }; "),"") | AM11: =CONCATENATE("};") -> };
A12: 1879490651 | C12: Birds of Ered Luin: Common and Uncommon | L12: 1 | O12: =IF(AND(A12>0,L12>0),CONCATENATE("[",A12,"] = ",L12,", // ",C12),"") -> [1879490651] = 1, // Birds of Ered Luin: Common and Uncommon | P12: =CONCATENATE(S12,U12,V12,AH12,AM12," -- ",C12) -> [11] = {["ID"] = 1879490651; ["TIER"] = 1; }; -- Birds of Ered Luin: Common and Uncommon | Q12: =CONCATENATE(S12,T12,W12,Y12,AA12,AC12,AE12,AG12,AH12,AI12,AJ12,AK12,AL12,AM12) -> #N/A | R12: =ROW()-1 -> 11 | S12: =CONCATENATE(REPT(" ",3-LEN(R12)),"[",R12,"] = {") -> [11] = { | T12: =IF(LEN(A12)>0,CONCATENATE("[""ID""] = ",A12,"; ")," ") -> ["ID"] = 1879490651; | U12: =IF(LEN(A12)>0,CONCATENATE("[""ID""] = ",A12,"; "),"") -> ["ID"] = 1879490651; | V12: =IF(LEN(M12)>0,CONCATENATE("[""CAT_ID""] = ",M12,"; "),"") | W12: =IF(LEN(B12)>0,CONCATENATE("[""SAVE_INDEX""] = ",REPT(" ",1-LEN(B12)),B12,"; "),"") | X12: =VLOOKUP(D12,Type!A$2:B$17,2,FALSE) -> #N/A | Y12: =CONCATENATE("[""TYPE""] = ",REPT(" ",2-LEN(X12)),X12,"; ") -> #N/A | Z12: =TEXT(E12,0) -> 0 | AA12: =CONCATENATE("[""VXP""] = ",REPT(" ",1-LEN(Z12)),TEXT(Z12,"0"),"; ") -> ["VXP"] = 0; | AB12: =TEXT(G12,0) -> 0 | AC12: =CONCATENATE("[""LP""] = ",REPT(" ",1-LEN(AB12)),TEXT(AB12,"0"),"; ") -> ["LP"] = 0; | AD12: =TEXT(H12,0) -> 0 | AE12: =CONCATENATE("[""REP""] = ",REPT(" ",1-LEN(AD12)),TEXT(AD12,"0"),"; ") -> ["REP"] = 0; | AF12: =VLOOKUP(I12,Faction!A$2:B$77,2,FALSE) -> #N/A | AG12: =CONCATENATE("[""FACTION""] = ",TEXT(AF12,"0"),"; ") -> #N/A | AH12: =IF(L12>0,CONCATENATE("[""TIER""] = ",TEXT(L12,"0"),"; "),"") -> ["TIER"] = 1; | AI12: =CONCATENATE("[""NAME""] = { [""EN""] = """,C12,"""; }; ") -> ["NAME"] = { ["EN"] = "Birds of Ered Luin: Common and Uncommon"; }; | AJ12: =CONCATENATE("[""LORE""] = { [""EN""] = """,K12,"""; }; ") -> ["LORE"] = { ["EN"] = ""; }; | AK12: =CONCATENATE("[""SUMMARY""] = { [""EN""] = """,J12,"""; }; ") -> ["SUMMARY"] = { ["EN"] = ""; }; | AL12: =IF(LEN(F12)>0,CONCATENATE("[""TITLE""] = { [""EN""] = """,F12,"""; }; "),"") | AM12: =CONCATENATE("};") -> };
A13: 1879490635 | C13: Birds of Ered Luin: Rare | L13: 1 | O13: =IF(AND(A13>0,L13>0),CONCATENATE("[",A13,"] = ",L13,", // ",C13),"") -> [1879490635] = 1, // Birds of Ered Luin: Rare | P13: =CONCATENATE(S13,U13,V13,AH13,AM13," -- ",C13) -> [12] = {["ID"] = 1879490635; ["TIER"] = 1; }; -- Birds of Ered Luin: Rare | Q13: =CONCATENATE(S13,T13,W13,Y13,AA13,AC13,AE13,AG13,AH13,AI13,AJ13,AK13,AL13,AM13) -> #N/A | R13: =ROW()-1 -> 12 | S13: =CONCATENATE(REPT(" ",3-LEN(R13)),"[",R13,"] = {") -> [12] = { | T13: =IF(LEN(A13)>0,CONCATENATE("[""ID""] = ",A13,"; ")," ") -> ["ID"] = 1879490635; | U13: =IF(LEN(A13)>0,CONCATENATE("[""ID""] = ",A13,"; "),"") -> ["ID"] = 1879490635; | V13: =IF(LEN(M13)>0,CONCATENATE("[""CAT_ID""] = ",M13,"; "),"") | W13: =IF(LEN(B13)>0,CONCATENATE("[""SAVE_INDEX""] = ",REPT(" ",1-LEN(B13)),B13,"; "),"") | X13: =VLOOKUP(D13,Type!A$2:B$17,2,FALSE) -> #N/A | Y13: =CONCATENATE("[""TYPE""] = ",REPT(" ",2-LEN(X13)),X13,"; ") -> #N/A | Z13: =TEXT(E13,0) -> 0 | AA13: =CONCATENATE("[""VXP""] = ",REPT(" ",1-LEN(Z13)),TEXT(Z13,"0"),"; ") -> ["VXP"] = 0; | AB13: =TEXT(G13,0) -> 0 | AC13: =CONCATENATE("[""LP""] = ",REPT(" ",1-LEN(AB13)),TEXT(AB13,"0"),"; ") -> ["LP"] = 0; | AD13: =TEXT(H13,0) -> 0 | AE13: =CONCATENATE("[""REP""] = ",REPT(" ",1-LEN(AD13)),TEXT(AD13,"0"),"; ") -> ["REP"] = 0; | AF13: =VLOOKUP(I13,Faction!A$2:B$77,2,FALSE) -> #N/A | AG13: =CONCATENATE("[""FACTION""] = ",TEXT(AF13,"0"),"; ") -> #N/A | AH13: =IF(L13>0,CONCATENATE("[""TIER""] = ",TEXT(L13,"0"),"; "),"") -> ["TIER"] = 1; | AI13: =CONCATENATE("[""NAME""] = { [""EN""] = """,C13,"""; }; ") -> ["NAME"] = { ["EN"] = "Birds of Ered Luin: Rare"; }; | AJ13: =CONCATENATE("[""LORE""] = { [""EN""] = """,K13,"""; }; ") -> ["LORE"] = { ["EN"] = ""; }; | AK13: =CONCATENATE("[""SUMMARY""] = { [""EN""] = """,J13,"""; }; ") -> ["SUMMARY"] = { ["EN"] = ""; }; | AL13: =IF(LEN(F13)>0,CONCATENATE("[""TITLE""] = { [""EN""] = """,F13,"""; }; "),"") | AM13: =CONCATENATE("};") -> };
A14: 1879490633 | C14: The Rarest Bird in Ered Luin | L14: 1 | O14: =IF(AND(A14>0,L14>0),CONCATENATE("[",A14,"] = ",L14,", // ",C14),"") -> [1879490633] = 1, // The Rarest Bird in Ered Luin | P14: =CONCATENATE(S14,U14,V14,AH14,AM14," -- ",C14) -> [13] = {["ID"] = 1879490633; ["TIER"] = 1; }; -- The Rarest Bird in Ered Luin | Q14: =CONCATENATE(S14,T14,W14,Y14,AA14,AC14,AE14,AG14,AH14,AI14,AJ14,AK14,AL14,AM14) -> #N/A | R14: =ROW()-1 -> 13 | S14: =CONCATENATE(REPT(" ",3-LEN(R14)),"[",R14,"] = {") -> [13] = { | T14: =IF(LEN(A14)>0,CONCATENATE("[""ID""] = ",A14,"; ")," ") -> ["ID"] = 1879490633; | U14: =IF(LEN(A14)>0,CONCATENATE("[""ID""] = ",A14,"; "),"") -> ["ID"] = 1879490633; | V14: =IF(LEN(M14)>0,CONCATENATE("[""CAT_ID""] = ",M14,"; "),"") | W14: =IF(LEN(B14)>0,CONCATENATE("[""SAVE_INDEX""] = ",REPT(" ",1-LEN(B14)),B14,"; "),"") | X14: =VLOOKUP(D14,Type!A$2:B$17,2,FALSE) -> #N/A | Y14: =CONCATENATE("[""TYPE""] = ",REPT(" ",2-LEN(X14)),X14,"; ") -> #N/A | Z14: =TEXT(E14,0) -> 0 | AA14: =CONCATENATE("[""VXP""] = ",REPT(" ",1-LEN(Z14)),TEXT(Z14,"0"),"; ") -> ["VXP"] = 0; | AB14: =TEXT(G14,0) -> 0 | AC14: =CONCATENATE("[""LP""] = ",REPT(" ",1-LEN(AB14)),TEXT(AB14,"0"),"; ") -> ["LP"] = 0; | AD14: =TEXT(H14,0) -> 0 | AE14: =CONCATENATE("[""REP""] = ",REPT(" ",1-LEN(AD14)),TEXT(AD14,"0"),"; ") -> ["REP"] = 0; | AF14: =VLOOKUP(I14,Faction!A$2:B$77,2,FALSE) -> #N/A | AG14: =CONCATENATE("[""FACTION""] = ",TEXT(AF14,"0"),"; ") -> #N/A | AH14: =IF(L14>0,CONCATENATE("[""TIER""] = ",TEXT(L14,"0"),"; "),"") -> ["TIER"] = 1; | AI14: =CONCATENATE("[""NAME""] = { [""EN""] = """,C14,"""; }; ") -> ["NAME"] = { ["EN"] = "The Rarest Bird in Ered Luin"; }; | AJ14: =CONCATENATE("[""LORE""] = { [""EN""] = """,K14,"""; }; ") -> ["LORE"] = { ["EN"] = ""; }; | AK14: =CONCATENATE("[""SUMMARY""] = { [""EN""] = """,J14,"""; }; ") -> ["SUMMARY"] = { ["EN"] = ""; }; | AL14: =IF(LEN(F14)>0,CONCATENATE("[""TITLE""] = { [""EN""] = """,F14,"""; }; "),"") | AM14: =CONCATENATE("};") -> };
A15: 1879490668 | C15: All the Birds of Swanfleet | L15: 0 | O15: =IF(AND(A15>0,L15>0),CONCATENATE("[",A15,"] = ",L15,", // ",C15),"") | P15: =CONCATENATE(S15,U15,V15,AH15,AM15," -- ",C15) -> [14] = {["ID"] = 1879490668; }; -- All the Birds of Swanfleet | Q15: =CONCATENATE(S15,T15,W15,Y15,AA15,AC15,AE15,AG15,AH15,AI15,AJ15,AK15,AL15,AM15) -> #N/A | R15: =ROW()-1 -> 14 | S15: =CONCATENATE(REPT(" ",3-LEN(R15)),"[",R15,"] = {") -> [14] = { | T15: =IF(LEN(A15)>0,CONCATENATE("[""ID""] = ",A15,"; ")," ") -> ["ID"] = 1879490668; | U15: =IF(LEN(A15)>0,CONCATENATE("[""ID""] = ",A15,"; "),"") -> ["ID"] = 1879490668; | V15: =IF(LEN(M15)>0,CONCATENATE("[""CAT_ID""] = ",M15,"; "),"") | W15: =IF(LEN(B15)>0,CONCATENATE("[""SAVE_INDEX""] = ",REPT(" ",1-LEN(B15)),B15,"; "),"") | X15: =VLOOKUP(D15,Type!A$2:B$17,2,FALSE) -> #N/A | Y15: =CONCATENATE("[""TYPE""] = ",REPT(" ",2-LEN(X15)),X15,"; ") -> #N/A | Z15: =TEXT(E15,0) -> 0 | AA15: =CONCATENATE("[""VXP""] = ",REPT(" ",1-LEN(Z15)),TEXT(Z15,"0"),"; ") -> ["VXP"] = 0; | AB15: =TEXT(G15,0) -> 0 | AC15: =CONCATENATE("[""LP""] = ",REPT(" ",1-LEN(AB15)),TEXT(AB15,"0"),"; ") -> ["LP"] = 0; | AD15: =TEXT(H15,0) -> 0 | AE15: =CONCATENATE("[""REP""] = ",REPT(" ",1-LEN(AD15)),TEXT(AD15,"0"),"; ") -> ["REP"] = 0; | AF15: =VLOOKUP(I15,Faction!A$2:B$77,2,FALSE) -> #N/A | AG15: =CONCATENATE("[""FACTION""] = ",TEXT(AF15,"0"),"; ") -> #N/A | AH15: =IF(L15>0,CONCATENATE("[""TIER""] = ",TEXT(L15,"0"),"; "),"") | AI15: =CONCATENATE("[""NAME""] = { [""EN""] = """,C15,"""; }; ") -> ["NAME"] = { ["EN"] = "All the Birds of Swanfleet"; }; | AJ15: =CONCATENATE("[""LORE""] = { [""EN""] = """,K15,"""; }; ") -> ["LORE"] = { ["EN"] = ""; }; | AK15: =CONCATENATE("[""SUMMARY""] = { [""EN""] = """,J15,"""; }; ") -> ["SUMMARY"] = { ["EN"] = ""; }; | AL15: =IF(LEN(F15)>0,CONCATENATE("[""TITLE""] = { [""EN""] = """,F15,"""; }; "),"") | AM15: =CONCATENATE("};") -> };
A16: 1879490642 | C16: Birds of Swanfleet: Common and Uncommon | L16: 1 | O16: =IF(AND(A16>0,L16>0),CONCATENATE("[",A16,"] = ",L16,", // ",C16),"") -> [1879490642] = 1, // Birds of Swanfleet: Common and Uncommon | P16: =CONCATENATE(S16,U16,V16,AH16,AM16," -- ",C16) -> [15] = {["ID"] = 1879490642; ["TIER"] = 1; }; -- Birds of Swanfleet: Common and Uncommon | Q16: =CONCATENATE(S16,T16,W16,Y16,AA16,AC16,AE16,AG16,AH16,AI16,AJ16,AK16,AL16,AM16) -> #N/A | R16: =ROW()-1 -> 15 | S16: =CONCATENATE(REPT(" ",3-LEN(R16)),"[",R16,"] = {") -> [15] = { | T16: =IF(LEN(A16)>0,CONCATENATE("[""ID""] = ",A16,"; ")," ") -> ["ID"] = 1879490642; | U16: =IF(LEN(A16)>0,CONCATENATE("[""ID""] = ",A16,"; "),"") -> ["ID"] = 1879490642; | V16: =IF(LEN(M16)>0,CONCATENATE("[""CAT_ID""] = ",M16,"; "),"") | W16: =IF(LEN(B16)>0,CONCATENATE("[""SAVE_INDEX""] = ",REPT(" ",1-LEN(B16)),B16,"; "),"") | X16: =VLOOKUP(D16,Type!A$2:B$17,2,FALSE) -> #N/A | Y16: =CONCATENATE("[""TYPE""] = ",REPT(" ",2-LEN(X16)),X16,"; ") -> #N/A | Z16: =TEXT(E16,0) -> 0 | AA16: =CONCATENATE("[""VXP""] = ",REPT(" ",1-LEN(Z16)),TEXT(Z16,"0"),"; ") -> ["VXP"] = 0; | AB16: =TEXT(G16,0) -> 0 | AC16: =CONCATENATE("[""LP""] = ",REPT(" ",1-LEN(AB16)),TEXT(AB16,"0"),"; ") -> ["LP"] = 0; | AD16: =TEXT(H16,0) -> 0 | AE16: =CONCATENATE("[""REP""] = ",REPT(" ",1-LEN(AD16)),TEXT(AD16,"0"),"; ") -> ["REP"] = 0; | AF16: =VLOOKUP(I16,Faction!A$2:B$77,2,FALSE) -> #N/A | AG16: =CONCATENATE("[""FACTION""] = ",TEXT(AF16,"0"),"; ") -> #N/A | AH16: =IF(L16>0,CONCATENATE("[""TIER""] = ",TEXT(L16,"0"),"; "),"") -> ["TIER"] = 1; | AI16: =CONCATENATE("[""NAME""] = { [""EN""] = """,C16,"""; }; ") -> ["NAME"] = { ["EN"] = "Birds of Swanfleet: Common and Uncommon"; }; | AJ16: =CONCATENATE("[""LORE""] = { [""EN""] = """,K16,"""; }; ") -> ["LORE"] = { ["EN"] = ""; }; | AK16: =CONCATENATE("[""SUMMARY""] = { [""EN""] = """,J16,"""; }; ") -> ["SUMMARY"] = { ["EN"] = ""; }; | AL16: =IF(LEN(F16)>0,CONCATENATE("[""TITLE""] = { [""EN""] = """,F16,"""; }; "),"") | AM16: =CONCATENATE("};") -> };
A17: 1879490641 | C17: Birds of Swanfleet: Rare | L17: 1 | O17: =IF(AND(A17>0,L17>0),CONCATENATE("[",A17,"] = ",L17,", // ",C17),"") -> [1879490641] = 1, // Birds of Swanfleet: Rare | P17: =CONCATENATE(S17,U17,V17,AH17,AM17," -- ",C17) -> [16] = {["ID"] = 1879490641; ["TIER"] = 1; }; -- Birds of Swanfleet: Rare | Q17: =CONCATENATE(S17,T17,W17,Y17,AA17,AC17,AE17,AG17,AH17,AI17,AJ17,AK17,AL17,AM17) -> #N/A | R17: =ROW()-1 -> 16 | S17: =CONCATENATE(REPT(" ",3-LEN(R17)),"[",R17,"] = {") -> [16] = { | T17: =IF(LEN(A17)>0,CONCATENATE("[""ID""] = ",A17,"; ")," ") -> ["ID"] = 1879490641; | U17: =IF(LEN(A17)>0,CONCATENATE("[""ID""] = ",A17,"; "),"") -> ["ID"] = 1879490641; | V17: =IF(LEN(M17)>0,CONCATENATE("[""CAT_ID""] = ",M17,"; "),"") | W17: =IF(LEN(B17)>0,CONCATENATE("[""SAVE_INDEX""] = ",REPT(" ",1-LEN(B17)),B17,"; "),"") | X17: =VLOOKUP(D17,Type!A$2:B$17,2,FALSE) -> #N/A | Y17: =CONCATENATE("[""TYPE""] = ",REPT(" ",2-LEN(X17)),X17,"; ") -> #N/A | Z17: =TEXT(E17,0) -> 0 | AA17: =CONCATENATE("[""VXP""] = ",REPT(" ",1-LEN(Z17)),TEXT(Z17,"0"),"; ") -> ["VXP"] = 0; | AB17: =TEXT(G17,0) -> 0 | AC17: =CONCATENATE("[""LP""] = ",REPT(" ",1-LEN(AB17)),TEXT(AB17,"0"),"; ") -> ["LP"] = 0; | AD17: =TEXT(H17,0) -> 0 | AE17: =CONCATENATE("[""REP""] = ",REPT(" ",1-LEN(AD17)),TEXT(AD17,"0"),"; ") -> ["REP"] = 0; | AF17: =VLOOKUP(I17,Faction!A$2:B$77,2,FALSE) -> #N/A | AG17: =CONCATENATE("[""FACTION""] = ",TEXT(AF17,"0"),"; ") -> #N/A | AH17: =IF(L17>0,CONCATENATE("[""TIER""] = ",TEXT(L17,"0"),"; "),"") -> ["TIER"] = 1; | AI17: =CONCATENATE("[""NAME""] = { [""EN""] = """,C17,"""; }; ") -> ["NAME"] = { ["EN"] = "Birds of Swanfleet: Rare"; }; | AJ17: =CONCATENATE("[""LORE""] = { [""EN""] = """,K17,"""; }; ") -> ["LORE"] = { ["EN"] = ""; }; | AK17: =CONCATENATE("[""SUMMARY""] = { [""EN""] = """,J17,"""; }; ") -> ["SUMMARY"] = { ["EN"] = ""; }; | AL17: =IF(LEN(F17)>0,CONCATENATE("[""TITLE""] = { [""EN""] = """,F17,"""; }; "),"") | AM17: =CONCATENATE("};") -> };
A18: 1879490645 | C18: The Rarest Bird in Swanfleet | L18: 1 | O18: =IF(AND(A18>0,L18>0),CONCATENATE("[",A18,"] = ",L18,", // ",C18),"") -> [1879490645] = 1, // The Rarest Bird in Swanfleet | P18: =CONCATENATE(S18,U18,V18,AH18,AM18," -- ",C18) -> [17] = {["ID"] = 1879490645; ["TIER"] = 1; }; -- The Rarest Bird in Swanfleet | Q18: =CONCATENATE(S18,T18,W18,Y18,AA18,AC18,AE18,AG18,AH18,AI18,AJ18,AK18,AL18,AM18) -> #N/A | R18: =ROW()-1 -> 17 | S18: =CONCATENATE(REPT(" ",3-LEN(R18)),"[",R18,"] = {") -> [17] = { | T18: =IF(LEN(A18)>0,CONCATENATE("[""ID""] = ",A18,"; ")," ") -> ["ID"] = 1879490645; | U18: =IF(LEN(A18)>0,CONCATENATE("[""ID""] = ",A18,"; "),"") -> ["ID"] = 1879490645; | V18: =IF(LEN(M18)>0,CONCATENATE("[""CAT_ID""] = ",M18,"; "),"") | W18: =IF(LEN(B18)>0,CONCATENATE("[""SAVE_INDEX""] = ",REPT(" ",1-LEN(B18)),B18,"; "),"") | X18: =VLOOKUP(D18,Type!A$2:B$17,2,FALSE) -> #N/A | Y18: =CONCATENATE("[""TYPE""] = ",REPT(" ",2-LEN(X18)),X18,"; ") -> #N/A | Z18: =TEXT(E18,0) -> 0 | AA18: =CONCATENATE("[""VXP""] = ",REPT(" ",1-LEN(Z18)),TEXT(Z18,"0"),"; ") -> ["VXP"] = 0; | AB18: =TEXT(G18,0) -> 0 | AC18: =CONCATENATE("[""LP""] = ",REPT(" ",1-LEN(AB18)),TEXT(AB18,"0"),"; ") -> ["LP"] = 0; | AD18: =TEXT(H18,0) -> 0 | AE18: =CONCATENATE("[""REP""] = ",REPT(" ",1-LEN(AD18)),TEXT(AD18,"0"),"; ") -> ["REP"] = 0; | AF18: =VLOOKUP(I18,Faction!A$2:B$77,2,FALSE) -> #N/A | AG18: =CONCATENATE("[""FACTION""] = ",TEXT(AF18,"0"),"; ") -> #N/A | AH18: =IF(L18>0,CONCATENATE("[""TIER""] = ",TEXT(L18,"0"),"; "),"") -> ["TIER"] = 1; | AI18: =CONCATENATE("[""NAME""] = { [""EN""] = """,C18,"""; }; ") -> ["NAME"] = { ["EN"] = "The Rarest Bird in Swanfleet"; }; | AJ18: =CONCATENATE("[""LORE""] = { [""EN""] = """,K18,"""; }; ") -> ["LORE"] = { ["EN"] = ""; }; | AK18: =CONCATENATE("[""SUMMARY""] = { [""EN""] = """,J18,"""; }; ") -> ["SUMMARY"] = { ["EN"] = ""; }; | AL18: =IF(LEN(F18)>0,CONCATENATE("[""TITLE""] = { [""EN""] = """,F18,"""; }; "),"") | AM18: =CONCATENATE("};") -> };
A19: 1879490670 | C19: All the Birds of Cardolan | L19: 0 | O19: =IF(AND(A19>0,L19>0),CONCATENATE("[",A19,"] = ",L19,", // ",C19),"") | P19: =CONCATENATE(S19,U19,V19,AH19,AM19," -- ",C19) -> [18] = {["ID"] = 1879490670; }; -- All the Birds of Cardolan | Q19: =CONCATENATE(S19,T19,W19,Y19,AA19,AC19,AE19,AG19,AH19,AI19,AJ19,AK19,AL19,AM19) -> #N/A | R19: =ROW()-1 -> 18 | S19: =CONCATENATE(REPT(" ",3-LEN(R19)),"[",R19,"] = {") -> [18] = { | T19: =IF(LEN(A19)>0,CONCATENATE("[""ID""] = ",A19,"; ")," ") -> ["ID"] = 1879490670; | U19: =IF(LEN(A19)>0,CONCATENATE("[""ID""] = ",A19,"; "),"") -> ["ID"] = 1879490670; | V19: =IF(LEN(M19)>0,CONCATENATE("[""CAT_ID""] = ",M19,"; "),"") | W19: =IF(LEN(B19)>0,CONCATENATE("[""SAVE_INDEX""] = ",REPT(" ",1-LEN(B19)),B19,"; "),"") | X19: =VLOOKUP(D19,Type!A$2:B$17,2,FALSE) -> #N/A | Y19: =CONCATENATE("[""TYPE""] = ",REPT(" ",2-LEN(X19)),X19,"; ") -> #N/A | Z19: =TEXT(E19,0) -> 0 | AA19: =CONCATENATE("[""VXP""] = ",REPT(" ",1-LEN(Z19)),TEXT(Z19,"0"),"; ") -> ["VXP"] = 0; | AB19: =TEXT(G19,0) -> 0 | AC19: =CONCATENATE("[""LP""] = ",REPT(" ",1-LEN(AB19)),TEXT(AB19,"0"),"; ") -> ["LP"] = 0; | AD19: =TEXT(H19,0) -> 0 | AE19: =CONCATENATE("[""REP""] = ",REPT(" ",1-LEN(AD19)),TEXT(AD19,"0"),"; ") -> ["REP"] = 0; | AF19: =VLOOKUP(I19,Faction!A$2:B$77,2,FALSE) -> #N/A | AG19: =CONCATENATE("[""FACTION""] = ",TEXT(AF19,"0"),"; ") -> #N/A | AH19: =IF(L19>0,CONCATENATE("[""TIER""] = ",TEXT(L19,"0"),"; "),"") | AI19: =CONCATENATE("[""NAME""] = { [""EN""] = """,C19,"""; }; ") -> ["NAME"] = { ["EN"] = "All the Birds of Cardolan"; }; | AJ19: =CONCATENATE("[""LORE""] = { [""EN""] = """,K19,"""; }; ") -> ["LORE"] = { ["EN"] = ""; }; | AK19: =CONCATENATE("[""SUMMARY""] = { [""EN""] = """,J19,"""; }; ") -> ["SUMMARY"] = { ["EN"] = ""; }; | AL19: =IF(LEN(F19)>0,CONCATENATE("[""TITLE""] = { [""EN""] = """,F19,"""; }; "),"") | AM19: =CONCATENATE("};") -> };
A20: 1879490621 | C20: Birds of Cardolan: Common and Uncommon | L20: 1 | O20: =IF(AND(A20>0,L20>0),CONCATENATE("[",A20,"] = ",L20,", // ",C20),"") -> [1879490621] = 1, // Birds of Cardolan: Common and Uncommon | P20: =CONCATENATE(S20,U20,V20,AH20,AM20," -- ",C20) -> [19] = {["ID"] = 1879490621; ["TIER"] = 1; }; -- Birds of Cardolan: Common and Uncommon | Q20: =CONCATENATE(S20,T20,W20,Y20,AA20,AC20,AE20,AG20,AH20,AI20,AJ20,AK20,AL20,AM20) -> #N/A | R20: =ROW()-1 -> 19 | S20: =CONCATENATE(REPT(" ",3-LEN(R20)),"[",R20,"] = {") -> [19] = { | T20: =IF(LEN(A20)>0,CONCATENATE("[""ID""] = ",A20,"; ")," ") -> ["ID"] = 1879490621; | U20: =IF(LEN(A20)>0,CONCATENATE("[""ID""] = ",A20,"; "),"") -> ["ID"] = 1879490621; | V20: =IF(LEN(M20)>0,CONCATENATE("[""CAT_ID""] = ",M20,"; "),"") | W20: =IF(LEN(B20)>0,CONCATENATE("[""SAVE_INDEX""] = ",REPT(" ",1-LEN(B20)),B20,"; "),"") | X20: =VLOOKUP(D20,Type!A$2:B$17,2,FALSE) -> #N/A | Y20: =CONCATENATE("[""TYPE""] = ",REPT(" ",2-LEN(X20)),X20,"; ") -> #N/A | Z20: =TEXT(E20,0) -> 0 | AA20: =CONCATENATE("[""VXP""] = ",REPT(" ",1-LEN(Z20)),TEXT(Z20,"0"),"; ") -> ["VXP"] = 0; | AB20: =TEXT(G20,0) -> 0 | AC20: =CONCATENATE("[""LP""] = ",REPT(" ",1-LEN(AB20)),TEXT(AB20,"0"),"; ") -> ["LP"] = 0; | AD20: =TEXT(H20,0) -> 0 | AE20: =CONCATENATE("[""REP""] = ",REPT(" ",1-LEN(AD20)),TEXT(AD20,"0"),"; ") -> ["REP"] = 0; | AF20: =VLOOKUP(I20,Faction!A$2:B$77,2,FALSE) -> #N/A | AG20: =CONCATENATE("[""FACTION""] = ",TEXT(AF20,"0"),"; ") -> #N/A | AH20: =IF(L20>0,CONCATENATE("[""TIER""] = ",TEXT(L20,"0"),"; "),"") -> ["TIER"] = 1; | AI20: =CONCATENATE("[""NAME""] = { [""EN""] = """,C20,"""; }; ") -> ["NAME"] = { ["EN"] = "Birds of Cardolan: Common and Uncommon"; }; | AJ20: =CONCATENATE("[""LORE""] = { [""EN""] = """,K20,"""; }; ") -> ["LORE"] = { ["EN"] = ""; }; | AK20: =CONCATENATE("[""SUMMARY""] = { [""EN""] = """,J20,"""; }; ") -> ["SUMMARY"] = { ["EN"] = ""; }; | AL20: =IF(LEN(F20)>0,CONCATENATE("[""TITLE""] = { [""EN""] = """,F20,"""; }; "),"") | AM20: =CONCATENATE("};") -> };
... A63: 1879490679 | C63: The Rarest of Birds in Eriador | L63: 0 | O63: =IF(AND(A63>0,L63>0),CONCATENATE("[",A63,"] = ",L63,", // ",C63),"") | P63: =CONCATENATE(S63,U63,V63,AH63,AM63," -- ",C63) -> [62] = {["ID"] = 1879490679; }; -- The Rarest of Birds in Eriador | Q63: =CONCATENATE(S63,T63,W63,Y63,AA63,AC63,AE63,AG63,AH63,AI63,AJ63,AK63,AL63,AM63) -> #N/A | R63: =ROW()-1 -> 62 | S63: =CONCATENATE(REPT(" ",3-LEN(R63)),"[",R63,"] = {") -> [62] = { | T63: =IF(LEN(A63)>0,CONCATENATE("[""ID""] = ",A63,"; ")," ") -> ["ID"] = 1879490679; | U63: =IF(LEN(A63)>0,CONCATENATE("[""ID""] = ",A63,"; "),"") -> ["ID"] = 1879490679; | V63: =IF(LEN(M63)>0,CONCATENATE("[""CAT_ID""] = ",M63,"; "),"") | W63: =IF(LEN(B63)>0,CONCATENATE("[""SAVE_INDEX""] = ",REPT(" ",1-LEN(B63)),B63,"; "),"") | X63: =VLOOKUP(D63,Type!A$2:B$17,2,FALSE) -> #N/A | Y63: =CONCATENATE("[""TYPE""] = ",REPT(" ",2-LEN(X63)),X63,"; ") -> #N/A | Z63: =TEXT(E63,0) -> 0 | AA63: =CONCATENATE("[""VXP""] = ",REPT(" ",1-LEN(Z63)),TEXT(Z63,"0"),"; ") -> ["VXP"] = 0; | AB63: =TEXT(G63,0) -> 0 | AC63: =CONCATENATE("[""LP""] = ",REPT(" ",1-LEN(AB63)),TEXT(AB63,"0"),"; ") -> ["LP"] = 0; | AD63: =TEXT(H63,0) -> 0 | AE63: =CONCATENATE("[""REP""] = ",REPT(" ",1-LEN(AD63)),TEXT(AD63,"0"),"; ") -> ["REP"] = 0; | AF63: =VLOOKUP(I63,Faction!A$2:B$77,2,FALSE) -> #N/A | AG63: =CONCATENATE("[""FACTION""] = ",TEXT(AF63,"0"),"; ") -> #N/A | AH63: =IF(L63>0,CONCATENATE("[""TIER""] = ",TEXT(L63,"0"),"; "),"") | AI63: =CONCATENATE("[""NAME""] = { [""EN""] = """,C63,"""; }; ") -> ["NAME"] = { ["EN"] = "The Rarest of Birds in Eriador"; }; | AJ63: =CONCATENATE("[""LORE""] = { [""EN""] = """,K63,"""; }; ") -> ["LORE"] = { ["EN"] = ""; }; | AK63: =CONCATENATE("[""SUMMARY""] = { [""EN""] = """,J63,"""; }; ") -> ["SUMMARY"] = { ["EN"] = ""; }; | AL63: =IF(LEN(F63)>0,CONCATENATE("[""TITLE""] = { [""EN""] = """,F63,"""; }; "),"") | AM63: =CONCATENATE("};") -> };
C64: Rohan and the Great River | D64: Category | M64: 321 | O64: =IF(AND(A64>0,L64>0),CONCATENATE("[",A64,"] = ",L64,", // ",C64),"") | P64: =CONCATENATE(S64,U64,V64,AH64,AM64," -- ",C64) -> [63] = {["CAT_ID"] = 321; }; -- Rohan and the Great River | Q64: =CONCATENATE(S64,T64,W64,Y64,AA64,AC64,AE64,AG64,AH64,AI64,AJ64,AK64,AL64,AM64) -> #N/A | R64: =ROW()-1 -> 63 | S64: =CONCATENATE(REPT(" ",3-LEN(R64)),"[",R64,"] = {") -> [63] = { | T64: =IF(LEN(A64)>0,CONCATENATE("[""ID""] = ",A64,"; ")," ") | U64: =IF(LEN(A64)>0,CONCATENATE("[""ID""] = ",A64,"; "),"") | V64: =IF(LEN(M64)>0,CONCATENATE("[""CAT_ID""] = ",M64,"; "),"") -> ["CAT_ID"] = 321; | W64: =IF(LEN(B64)>0,CONCATENATE("[""SAVE_INDEX""] = ",REPT(" ",1-LEN(B64)),B64,"; "),"") | X64: =VLOOKUP(D64,Type!A$2:B$17,2,FALSE) -> 14 | Y64: =CONCATENATE("[""TYPE""] = ",REPT(" ",2-LEN(X64)),X64,"; ") -> ["TYPE"] = 14; | Z64: =TEXT(E64,0) -> 0 | AA64: =CONCATENATE("[""VXP""] = ",REPT(" ",1-LEN(Z64)),TEXT(Z64,"0"),"; ") -> ["VXP"] = 0; | AB64: =TEXT(G64,0) -> 0 | AC64: =CONCATENATE("[""LP""] = ",REPT(" ",1-LEN(AB64)),TEXT(AB64,"0"),"; ") -> ["LP"] = 0; | AD64: =TEXT(H64,0) -> 0 | AE64: =CONCATENATE("[""REP""] = ",REPT(" ",1-LEN(AD64)),TEXT(AD64,"0"),"; ") -> ["REP"] = 0; | AF64: =VLOOKUP(I64,Faction!A$2:B$77,2,FALSE) -> #N/A | AG64: =CONCATENATE("[""FACTION""] = ",TEXT(AF64,"0"),"; ") -> #N/A | AH64: =IF(L64>0,CONCATENATE("[""TIER""] = ",TEXT(L64,"0"),"; "),"") | AI64: =CONCATENATE("[""NAME""] = { [""EN""] = """,C64,"""; }; ") -> ["NAME"] = { ["EN"] = "Rohan and the Great River"; }; | AJ64: =CONCATENATE("[""LORE""] = { [""EN""] = """,K64,"""; }; ") -> ["LORE"] = { ["EN"] = ""; }; | AK64: =CONCATENATE("[""SUMMARY""] = { [""EN""] = """,J64,"""; }; ") -> ["SUMMARY"] = { ["EN"] = ""; }; | AL64: =IF(LEN(F64)>0,CONCATENATE("[""TITLE""] = { [""EN""] = """,F64,"""; }; "),"") | AM64: =CONCATENATE("};") -> };
A65: 1879501132 | C65: All the Birds of Lothlórien | L65: 0 | O65: =IF(AND(A65>0,L65>0),CONCATENATE("[",A65,"] = ",L65,", // ",C65),"") | P65: =CONCATENATE(S65,U65,V65,AH65,AM65," -- ",C65) -> [64] = {["ID"] = 1879501132; }; -- All the Birds of Lothlórien | Q65: =CONCATENATE(S65,T65,W65,Y65,AA65,AC65,AE65,AG65,AH65,AI65,AJ65,AK65,AL65,AM65) -> #N/A | R65: =ROW()-1 -> 64 | S65: =CONCATENATE(REPT(" ",3-LEN(R65)),"[",R65,"] = {") -> [64] = { | T65: =IF(LEN(A65)>0,CONCATENATE("[""ID""] = ",A65,"; ")," ") -> ["ID"] = 1879501132; | U65: =IF(LEN(A65)>0,CONCATENATE("[""ID""] = ",A65,"; "),"") -> ["ID"] = 1879501132; | V65: =IF(LEN(M65)>0,CONCATENATE("[""CAT_ID""] = ",M65,"; "),"") | W65: =IF(LEN(B65)>0,CONCATENATE("[""SAVE_INDEX""] = ",REPT(" ",1-LEN(B65)),B65,"; "),"") | X65: =VLOOKUP(D65,Type!A$2:B$17,2,FALSE) -> #N/A | Y65: =CONCATENATE("[""TYPE""] = ",REPT(" ",2-LEN(X65)),X65,"; ") -> #N/A | Z65: =TEXT(E65,0) -> 0 | AA65: =CONCATENATE("[""VXP""] = ",REPT(" ",1-LEN(Z65)),TEXT(Z65,"0"),"; ") -> ["VXP"] = 0; | AB65: =TEXT(G65,0) -> 0 | AC65: =CONCATENATE("[""LP""] = ",REPT(" ",1-LEN(AB65)),TEXT(AB65,"0"),"; ") -> ["LP"] = 0; | AD65: =TEXT(H65,0) -> 0 | AE65: =CONCATENATE("[""REP""] = ",REPT(" ",1-LEN(AD65)),TEXT(AD65,"0"),"; ") -> ["REP"] = 0; | AF65: =VLOOKUP(I65,Faction!A$2:B$77,2,FALSE) -> #N/A | AG65: =CONCATENATE("[""FACTION""] = ",TEXT(AF65,"0"),"; ") -> #N/A | AH65: =IF(L65>0,CONCATENATE("[""TIER""] = ",TEXT(L65,"0"),"; "),"") | AI65: =CONCATENATE("[""NAME""] = { [""EN""] = """,C65,"""; }; ") -> ["NAME"] = { ["EN"] = "All the Birds of Lothlórien"; }; | AJ65: =CONCATENATE("[""LORE""] = { [""EN""] = """,K65,"""; }; ") -> ["LORE"] = { ["EN"] = ""; }; | AK65: =CONCATENATE("[""SUMMARY""] = { [""EN""] = """,J65,"""; }; ") -> ["SUMMARY"] = { ["EN"] = ""; }; | AL65: =IF(LEN(F65)>0,CONCATENATE("[""TITLE""] = { [""EN""] = """,F65,"""; }; "),"") | AM65: =CONCATENATE("};") -> };
